<?xml version="1.0" ?>
<!-- =================================================================================== -->
<!-- |    This document was autogenerated by xacro from /disk/users/pfotzer/workspace/plexnav/catkin_ws/src/lauron_description/urdf/lauron_standalone.urdf.xacro | -->
<!-- |    EDITING THIS FILE BY HAND IS NOT RECOMMENDED                                 | -->
<!-- =================================================================================== -->
<robot name="lauron" xmlns:xacro="http://www.ros.org/wiki/xacro">
  <!-- Required arguments:
       tf_prefix : a prefix for all the tf frames
       ns : namespace for robot topics
  -->
  <!-- create Lauron V instance from included macro -->
  <link name="robot_base_link"/>
  <link name="robot_base_link_torso">
    <visual>
      <geometry>
        <mesh filename="model://hbpprak_locomotion/meshes/TORSO_low.dae"/>
      </geometry>
    </visual>
    <inertial>
      <mass value="12.0"/>
      <inertia ixx="0.01" ixy="0.0" ixz="0.0" iyy="0.01" iyz="0.0" izz="0.01"/>
    </inertial>
    <collision>
      <origin rpy="0 0 0" xyz="-0.12 0 0.025"/>
      <geometry>
        <box size="0.85 0.37 0.26"/>
      </geometry>
    </collision>
  </link>
  <link name="robot_base_imu_pitch_link">
    <inertial>
      <mass value="0.0001"/>
      <inertia ixx="0.01" ixy="0.0" ixz="0.0" iyy="0.01" iyz="0.0" izz="0.01"/>
    </inertial>
  </link>
  <link name="robot_base_leveled_link">
    <inertial>
      <mass value="0.0001"/>
      <inertia ixx="0.01" ixy="0.0" ixz="0.0" iyy="0.01" iyz="0.0" izz="0.01"/>
    </inertial>
  </link>
  <joint name="robot_base_link_torso_joint" type="fixed">
    <parent link="robot_base_link"/>
    <child link="robot_base_link_torso"/>
    <origin rpy="0 0 0" xyz="0 0 0"/>
  </joint>
  <joint name="robot_IMU_pitch_joint" type="revolute">
    <parent link="robot_base_link"/>
    <child link="robot_base_imu_pitch_link"/>
    <axis xyz="0 -1 0"/>
    <limit effort="0" lower="-3.14" upper="3.14" velocity="10.0"/>
  </joint>
  <joint name="robot_IMU_roll_joint" type="revolute">
    <parent link="robot_base_imu_pitch_link"/>
    <child link="robot_base_leveled_link"/>
    <axis xyz="-1 0 0"/>
    <limit effort="0" lower="-3.14" upper="3.14" velocity="10.0"/>
  </joint>
  <link name="robot_leg0_base_link"/>
  <link name="robot_leg0_body_link">
    <visual>
      <origin rpy="0 -1.5708 0" xyz="0 0 0"/>
      <geometry>
        <mesh filename="model://hbpprak_locomotion/meshes/leg/LEG_CON_low.dae"/>
      </geometry>
    </visual>
    <inertial>
      <mass value="1.0"/>
      <inertia ixx="0.01" ixy="0.0" ixz="0.0" iyy="0.01" iyz="0.0" izz="0.01"/>
    </inertial>
  </link>
  <link name="robot_leg0_delta_link">
    <visual>
      <origin xyz="0 0 0.0721"/>
      <geometry>
        <mesh filename="model://hbpprak_locomotion/meshes/leg/DELTA_low.dae"/>
      </geometry>
    </visual>
    <inertial>
      <mass value="1.0"/>
      <inertia ixx="0.01" ixy="0.0" ixz="0.0" iyy="0.01" iyz="0.0" izz="0.01"/>
    </inertial>
  </link>
  <link name="robot_leg0_alpha_link">
    <visual>
      <geometry>
        <mesh filename="model://hbpprak_locomotion/meshes/leg/ALPHA_low.dae"/>
      </geometry>
      <origin rpy="0 0 1.5708" xyz="0 0 0"/>
    </visual>
    <inertial>
      <mass value="1.0"/>
      <inertia ixx="0.01" ixy="0.0" ixz="0.0" iyy="0.01" iyz="0.0" izz="0.01"/>
    </inertial>
  </link>
  <link name="robot_leg0_beta_link">
    <visual>
      <geometry>
        <mesh filename="model://hbpprak_locomotion/meshes/leg/BETA_low.dae"/>
      </geometry>
    </visual>
    <inertial>
      <mass value="1.0"/>
      <inertia ixx="0.01" ixy="0.0" ixz="0.0" iyy="0.01" iyz="0.0" izz="0.01"/>
    </inertial>
    <collision>
      <origin rpy="0 0 0" xyz="0.085 -0.01 0"/>
      <geometry>
        <box size="0.22 0.12 0.03"/>
      </geometry>
    </collision>
  </link>
  <link name="robot_leg0_beta_fixed_link">
    <inertial>
      <mass value="0.01"/>
      <inertia ixx="0.01" ixy="0.0" ixz="0.0" iyy="0.01" iyz="0.0" izz="0.01"/>
    </inertial>
  </link>
  <link name="robot_leg0_gamma_link">
    <visual>
      <geometry>
        <mesh filename="model://hbpprak_locomotion/meshes/leg/GAMMA_low.dae"/>
      </geometry>
    </visual>
    <inertial>
      <mass value="1.0"/>
      <inertia ixx="0.01" ixy="0.0" ixz="0.0" iyy="0.01" iyz="0.0" izz="0.01"/>
    </inertial>
    <collision>
      <origin rpy="0 1.57 0" xyz="0.16 0.004 0"/>
      <geometry>
        <cylinder length="0.22" radius="0.03"/>
      </geometry>
      <contact_coefficients mu="5"/>
    </collision>
    <collision>
      <origin rpy="0 0 0" xyz="0.32 0 0"/>
      <geometry>
        <sphere radius="0.02"/>
      </geometry>
      <contact_coefficients mu="5"/>
    </collision>
  </link>
  <link name="robot_leg0_foot_link">
    <inertial>
      <mass value="0.01"/>
      <inertia ixx="0.01" ixy="0.0" ixz="0.0" iyy="0.01" iyz="0.0" izz="0.01"/>
    </inertial>
  </link>
  <joint name="robot_leg0_base_joint" type="fixed">
    <parent link="robot_base_link"/>
    <child link="robot_leg0_base_link"/>
    <origin rpy="0 0 0" xyz="0.22841 0.0806665 -0.056215"/>
  </joint>
  <joint name="robot_leg0_body_joint" type="fixed">
    <parent link="robot_leg0_base_link"/>
    <child link="robot_leg0_body_link"/>
    <origin rpy="-2.35620 0 -0.69813" xyz="0 0 0"/>
  </joint>
  <joint name="robot_leg0_delta_joint" type="revolute">
    <parent link="robot_leg0_body_link"/>
    <child link="robot_leg0_delta_link"/>
    <origin rpy="0 0 0" xyz="0 0 0"/>
    <axis xyz="0 0 1"/>
    <limit effort="100" lower="-1.22173" upper="1.22173" velocity="10.0"/>
  </joint>
  <joint name="robot_leg0_alpha_joint" type="revolute">
    <parent link="robot_leg0_delta_link"/>
    <child link="robot_leg0_alpha_link"/>
    <!-- old alpha part: origin xyz="0 0 0.0565" rpy="1.5708 0 0" /-->
    <origin rpy="1.5708 0 0" xyz="0 0 0.0721"/>
    <axis xyz="0 0 1"/>
    <limit effort="100" lower="-1.22173" upper="1.22173" velocity="10.0"/>
  </joint>
  <joint name="robot_leg0_beta_fixed_joint" type="fixed">
    <parent link="robot_leg0_alpha_link"/>
    <child link="robot_leg0_beta_fixed_link"/>
    <!-- old alpha part: origin xyz="0 0.089 0" rpy="1.5708 0 0" /-->
    <origin rpy="1.5708 0 0" xyz="0 0.1097 0"/>
  </joint>
  <joint name="robot_leg0_beta_joint" type="revolute">
    <parent link="robot_leg0_beta_fixed_link"/>
    <child link="robot_leg0_beta_link"/>
    <origin rpy="0 1.5708 0" xyz="0 0 0"/>
    <axis xyz="0 0 1"/>
    <limit effort="100" lower="-0.69813" upper="2.21657" velocity="10.0"/>
  </joint>
  <joint name="robot_leg0_gamma_joint" type="revolute">
    <parent link="robot_leg0_beta_link"/>
    <child link="robot_leg0_gamma_link"/>
    <!-- old beta part: origin xyz="0.2 0 0" rpy="0 0 0" /-->
    <origin rpy="0 0 0" xyz="0.195 -0.0439 0"/>
    <axis xyz="0 0 1"/>
    <limit effort="100" lower="-2.6529" upper="0.24435" velocity="10.0"/>
  </joint>
  <joint name="robot_leg0_foot_joint" type="fixed">
    <parent link="robot_leg0_gamma_link"/>
    <child link="robot_leg0_foot_link"/>
    <origin rpy="0 0 0" xyz="0.335 0 0"/>
  </joint>
  <transmission name="robot_leg0_delta_joint_tran">
    <type>transmission_interface/SimpleTransmission</type>
    <joint name="robot_leg0_delta_joint">
      <hardwareInterface>EffortJointInterface</hardwareInterface>
    </joint>
    <actuator name="robot_leg0_delta_joint_motor">
      <hardwareInterface>EffortJointInterface</hardwareInterface>
      <mechanicalReduction>1</mechanicalReduction>
    </actuator>
  </transmission>
  <transmission name="robot_leg0_alpha_joint_tran">
    <type>transmission_interface/SimpleTransmission</type>
    <joint name="robot_leg0_alpha_joint">
      <hardwareInterface>EffortJointInterface</hardwareInterface>
    </joint>
    <actuator name="robot_leg0_alpha_joint_motor">
      <hardwareInterface>EffortJointInterface</hardwareInterface>
      <mechanicalReduction>1</mechanicalReduction>
    </actuator>
  </transmission>
  <transmission name="robot_leg0_beta_joint_tran">
    <type>transmission_interface/SimpleTransmission</type>
    <joint name="robot_leg0_beta_joint">
      <hardwareInterface>EffortJointInterface</hardwareInterface>
    </joint>
    <actuator name="robot_leg0_beta_joint_motor">
      <hardwareInterface>EffortJointInterface</hardwareInterface>
      <mechanicalReduction>1</mechanicalReduction>
    </actuator>
  </transmission>
  <transmission name="robot_leg0_gamma_joint_tran">
    <type>transmission_interface/SimpleTransmission</type>
    <joint name="robot_leg0_gamma_joint">
      <hardwareInterface>EffortJointInterface</hardwareInterface>
    </joint>
    <actuator name="robot_leg0_gamma_joint_motor">
      <hardwareInterface>EffortJointInterface</hardwareInterface>
      <mechanicalReduction>1</mechanicalReduction>
    </actuator>
  </transmission>
  <link name="robot_leg1_base_link"/>
  <link name="robot_leg1_body_link">
    <visual>
      <origin rpy="0 -1.5708 0" xyz="0 0 0"/>
      <geometry>
        <mesh filename="model://hbpprak_locomotion/meshes/leg/LEG_CON_low.dae"/>
      </geometry>
    </visual>
    <inertial>
      <mass value="1.0"/>
      <inertia ixx="0.01" ixy="0.0" ixz="0.0" iyy="0.01" iyz="0.0" izz="0.01"/>
    </inertial>
  </link>
  <link name="robot_leg1_delta_link">
    <visual>
      <origin xyz="0 0 0.0721"/>
      <geometry>
        <mesh filename="model://hbpprak_locomotion/meshes/leg/DELTA_low.dae"/>
      </geometry>
    </visual>
    <inertial>
      <mass value="1.0"/>
      <inertia ixx="0.01" ixy="0.0" ixz="0.0" iyy="0.01" iyz="0.0" izz="0.01"/>
    </inertial>
  </link>
  <link name="robot_leg1_alpha_link">
    <visual>
      <geometry>
        <mesh filename="model://hbpprak_locomotion/meshes/leg/ALPHA_low.dae"/>
      </geometry>
      <origin rpy="0 0 1.5708" xyz="0 0 0"/>
    </visual>
    <inertial>
      <mass value="1.0"/>
      <inertia ixx="0.01" ixy="0.0" ixz="0.0" iyy="0.01" iyz="0.0" izz="0.01"/>
    </inertial>
  </link>
  <link name="robot_leg1_beta_link">
    <visual>
      <geometry>
        <mesh filename="model://hbpprak_locomotion/meshes/leg/BETA_low.dae"/>
      </geometry>
    </visual>
    <inertial>
      <mass value="1.0"/>
      <inertia ixx="0.01" ixy="0.0" ixz="0.0" iyy="0.01" iyz="0.0" izz="0.01"/>
    </inertial>
    <collision>
      <origin rpy="0 0 0" xyz="0.085 -0.01 0"/>
      <geometry>
        <box size="0.22 0.12 0.03"/>
      </geometry>
    </collision>
  </link>
  <link name="robot_leg1_beta_fixed_link">
    <inertial>
      <mass value="0.01"/>
      <inertia ixx="0.01" ixy="0.0" ixz="0.0" iyy="0.01" iyz="0.0" izz="0.01"/>
    </inertial>
  </link>
  <link name="robot_leg1_gamma_link">
    <visual>
      <geometry>
        <mesh filename="model://hbpprak_locomotion/meshes/leg/GAMMA_low.dae"/>
      </geometry>
    </visual>
    <inertial>
      <mass value="1.0"/>
      <inertia ixx="0.01" ixy="0.0" ixz="0.0" iyy="0.01" iyz="0.0" izz="0.01"/>
    </inertial>
    <collision>
      <origin rpy="0 1.57 0" xyz="0.16 0.004 0"/>
      <geometry>
        <cylinder length="0.22" radius="0.03"/>
      </geometry>
      <contact_coefficients mu="5"/>
    </collision>
    <collision>
      <origin rpy="0 0 0" xyz="0.32 0 0"/>
      <geometry>
        <sphere radius="0.02"/>
      </geometry>
      <contact_coefficients mu="5"/>
    </collision>
  </link>
  <link name="robot_leg1_foot_link">
    <inertial>
      <mass value="0.01"/>
      <inertia ixx="0.01" ixy="0.0" ixz="0.0" iyy="0.01" iyz="0.0" izz="0.01"/>
    </inertial>
  </link>
  <joint name="robot_leg1_base_joint" type="fixed">
    <parent link="robot_base_link"/>
    <child link="robot_leg1_base_link"/>
    <origin rpy="0 0 0" xyz="0.22841 -0.0806665 -0.056215"/>
  </joint>
  <joint name="robot_leg1_body_joint" type="fixed">
    <parent link="robot_leg1_base_link"/>
    <child link="robot_leg1_body_link"/>
    <origin rpy="-2.35620 0 3.83972" xyz="0 0 0"/>
  </joint>
  <joint name="robot_leg1_delta_joint" type="revolute">
    <parent link="robot_leg1_body_link"/>
    <child link="robot_leg1_delta_link"/>
    <origin rpy="0 0 0" xyz="0 0 0"/>
    <axis xyz="0 0 1"/>
    <limit effort="100" lower="-1.22173" upper="1.22173" velocity="10.0"/>
  </joint>
  <joint name="robot_leg1_alpha_joint" type="revolute">
    <parent link="robot_leg1_delta_link"/>
    <child link="robot_leg1_alpha_link"/>
    <!-- old alpha part: origin xyz="0 0 0.0565" rpy="1.5708 0 0" /-->
    <origin rpy="1.5708 0 0" xyz="0 0 0.0721"/>
    <axis xyz="0 0 1"/>
    <limit effort="100" lower="-1.22173" upper="1.22173" velocity="10.0"/>
  </joint>
  <joint name="robot_leg1_beta_fixed_joint" type="fixed">
    <parent link="robot_leg1_alpha_link"/>
    <child link="robot_leg1_beta_fixed_link"/>
    <!-- old alpha part: origin xyz="0 0.089 0" rpy="1.5708 0 0" /-->
    <origin rpy="1.5708 0 0" xyz="0 0.1097 0"/>
  </joint>
  <joint name="robot_leg1_beta_joint" type="revolute">
    <parent link="robot_leg1_beta_fixed_link"/>
    <child link="robot_leg1_beta_link"/>
    <origin rpy="0 1.5708 0" xyz="0 0 0"/>
    <axis xyz="0 0 1"/>
    <limit effort="100" lower="-0.69813" upper="2.21657" velocity="10.0"/>
  </joint>
  <joint name="robot_leg1_gamma_joint" type="revolute">
    <parent link="robot_leg1_beta_link"/>
    <child link="robot_leg1_gamma_link"/>
    <!-- old beta part: origin xyz="0.2 0 0" rpy="0 0 0" /-->
    <origin rpy="0 0 0" xyz="0.195 -0.0439 0"/>
    <axis xyz="0 0 1"/>
    <limit effort="100" lower="-2.6529" upper="0.24435" velocity="10.0"/>
  </joint>
  <joint name="robot_leg1_foot_joint" type="fixed">
    <parent link="robot_leg1_gamma_link"/>
    <child link="robot_leg1_foot_link"/>
    <origin rpy="0 0 0" xyz="0.335 0 0"/>
  </joint>
  <transmission name="robot_leg1_delta_joint_tran">
    <type>transmission_interface/SimpleTransmission</type>
    <joint name="robot_leg1_delta_joint">
      <hardwareInterface>EffortJointInterface</hardwareInterface>
    </joint>
    <actuator name="robot_leg1_delta_joint_motor">
      <hardwareInterface>EffortJointInterface</hardwareInterface>
      <mechanicalReduction>1</mechanicalReduction>
    </actuator>
  </transmission>
  <transmission name="robot_leg1_alpha_joint_tran">
    <type>transmission_interface/SimpleTransmission</type>
    <joint name="robot_leg1_alpha_joint">
      <hardwareInterface>EffortJointInterface</hardwareInterface>
    </joint>
    <actuator name="robot_leg1_alpha_joint_motor">
      <hardwareInterface>EffortJointInterface</hardwareInterface>
      <mechanicalReduction>1</mechanicalReduction>
    </actuator>
  </transmission>
  <transmission name="robot_leg1_beta_joint_tran">
    <type>transmission_interface/SimpleTransmission</type>
    <joint name="robot_leg1_beta_joint">
      <hardwareInterface>EffortJointInterface</hardwareInterface>
    </joint>
    <actuator name="robot_leg1_beta_joint_motor">
      <hardwareInterface>EffortJointInterface</hardwareInterface>
      <mechanicalReduction>1</mechanicalReduction>
    </actuator>
  </transmission>
  <transmission name="robot_leg1_gamma_joint_tran">
    <type>transmission_interface/SimpleTransmission</type>
    <joint name="robot_leg1_gamma_joint">
      <hardwareInterface>EffortJointInterface</hardwareInterface>
    </joint>
    <actuator name="robot_leg1_gamma_joint_motor">
      <hardwareInterface>EffortJointInterface</hardwareInterface>
      <mechanicalReduction>1</mechanicalReduction>
    </actuator>
  </transmission>
  <link name="robot_leg2_base_link"/>
  <link name="robot_leg2_body_link">
    <visual>
      <origin rpy="0 -1.5708 0" xyz="0 0 0"/>
      <geometry>
        <mesh filename="model://hbpprak_locomotion/meshes/leg/LEG_CON_low.dae"/>
      </geometry>
    </visual>
    <inertial>
      <mass value="1.0"/>
      <inertia ixx="0.01" ixy="0.0" ixz="0.0" iyy="0.01" iyz="0.0" izz="0.01"/>
    </inertial>
  </link>
  <link name="robot_leg2_delta_link">
    <visual>
      <origin xyz="0 0 0.0721"/>
      <geometry>
        <mesh filename="model://hbpprak_locomotion/meshes/leg/DELTA_low.dae"/>
      </geometry>
    </visual>
    <inertial>
      <mass value="1.0"/>
      <inertia ixx="0.01" ixy="0.0" ixz="0.0" iyy="0.01" iyz="0.0" izz="0.01"/>
    </inertial>
  </link>
  <link name="robot_leg2_alpha_link">
    <visual>
      <geometry>
        <mesh filename="model://hbpprak_locomotion/meshes/leg/ALPHA_low.dae"/>
      </geometry>
      <origin rpy="0 0 1.5708" xyz="0 0 0"/>
    </visual>
    <inertial>
      <mass value="1.0"/>
      <inertia ixx="0.01" ixy="0.0" ixz="0.0" iyy="0.01" iyz="0.0" izz="0.01"/>
    </inertial>
  </link>
  <link name="robot_leg2_beta_link">
    <visual>
      <geometry>
        <mesh filename="model://hbpprak_locomotion/meshes/leg/BETA_low.dae"/>
      </geometry>
    </visual>
    <inertial>
      <mass value="1.0"/>
      <inertia ixx="0.01" ixy="0.0" ixz="0.0" iyy="0.01" iyz="0.0" izz="0.01"/>
    </inertial>
    <collision>
      <origin rpy="0 0 0" xyz="0.085 -0.01 0"/>
      <geometry>
        <box size="0.22 0.12 0.03"/>
      </geometry>
    </collision>
  </link>
  <link name="robot_leg2_beta_fixed_link">
    <inertial>
      <mass value="0.01"/>
      <inertia ixx="0.01" ixy="0.0" ixz="0.0" iyy="0.01" iyz="0.0" izz="0.01"/>
    </inertial>
  </link>
  <link name="robot_leg2_gamma_link">
    <visual>
      <geometry>
        <mesh filename="model://hbpprak_locomotion/meshes/leg/GAMMA_low.dae"/>
      </geometry>
    </visual>
    <inertial>
      <mass value="1.0"/>
      <inertia ixx="0.01" ixy="0.0" ixz="0.0" iyy="0.01" iyz="0.0" izz="0.01"/>
    </inertial>
    <collision>
      <origin rpy="0 1.57 0" xyz="0.16 0.004 0"/>
      <geometry>
        <cylinder length="0.22" radius="0.03"/>
      </geometry>
      <contact_coefficients mu="5"/>
    </collision>
    <collision>
      <origin rpy="0 0 0" xyz="0.32 0 0"/>
      <geometry>
        <sphere radius="0.02"/>
      </geometry>
      <contact_coefficients mu="5"/>
    </collision>
  </link>
  <link name="robot_leg2_foot_link">
    <inertial>
      <mass value="0.01"/>
      <inertia ixx="0.01" ixy="0.0" ixz="0.0" iyy="0.01" iyz="0.0" izz="0.01"/>
    </inertial>
  </link>
  <joint name="robot_leg2_base_joint" type="fixed">
    <parent link="robot_base_link"/>
    <child link="robot_leg2_base_link"/>
    <origin rpy="0 0 0" xyz="-0.0673369 0.0962107 -0.056215"/>
  </joint>
  <joint name="robot_leg2_body_joint" type="fixed">
    <parent link="robot_leg2_base_link"/>
    <child link="robot_leg2_body_link"/>
    <origin rpy="-2.35620 0 -0.349066" xyz="0 0 0"/>
  </joint>
  <joint name="robot_leg2_delta_joint" type="revolute">
    <parent link="robot_leg2_body_link"/>
    <child link="robot_leg2_delta_link"/>
    <origin rpy="0 0 0" xyz="0 0 0"/>
    <axis xyz="0 0 1"/>
    <limit effort="100" lower="-1.22173" upper="1.22173" velocity="10.0"/>
  </joint>
  <joint name="robot_leg2_alpha_joint" type="revolute">
    <parent link="robot_leg2_delta_link"/>
    <child link="robot_leg2_alpha_link"/>
    <!-- old alpha part: origin xyz="0 0 0.0565" rpy="1.5708 0 0" /-->
    <origin rpy="1.5708 0 0" xyz="0 0 0.0721"/>
    <axis xyz="0 0 1"/>
    <limit effort="100" lower="-1.22173" upper="1.22173" velocity="10.0"/>
  </joint>
  <joint name="robot_leg2_beta_fixed_joint" type="fixed">
    <parent link="robot_leg2_alpha_link"/>
    <child link="robot_leg2_beta_fixed_link"/>
    <!-- old alpha part: origin xyz="0 0.089 0" rpy="1.5708 0 0" /-->
    <origin rpy="1.5708 0 0" xyz="0 0.1097 0"/>
  </joint>
  <joint name="robot_leg2_beta_joint" type="revolute">
    <parent link="robot_leg2_beta_fixed_link"/>
    <child link="robot_leg2_beta_link"/>
    <origin rpy="0 1.5708 0" xyz="0 0 0"/>
    <axis xyz="0 0 1"/>
    <limit effort="100" lower="-0.69813" upper="2.21657" velocity="10.0"/>
  </joint>
  <joint name="robot_leg2_gamma_joint" type="revolute">
    <parent link="robot_leg2_beta_link"/>
    <child link="robot_leg2_gamma_link"/>
    <!-- old beta part: origin xyz="0.2 0 0" rpy="0 0 0" /-->
    <origin rpy="0 0 0" xyz="0.195 -0.0439 0"/>
    <axis xyz="0 0 1"/>
    <limit effort="100" lower="-2.6529" upper="0.24435" velocity="10.0"/>
  </joint>
  <joint name="robot_leg2_foot_joint" type="fixed">
    <parent link="robot_leg2_gamma_link"/>
    <child link="robot_leg2_foot_link"/>
    <origin rpy="0 0 0" xyz="0.335 0 0"/>
  </joint>
  <transmission name="robot_leg2_delta_joint_tran">
    <type>transmission_interface/SimpleTransmission</type>
    <joint name="robot_leg2_delta_joint">
      <hardwareInterface>EffortJointInterface</hardwareInterface>
    </joint>
    <actuator name="robot_leg2_delta_joint_motor">
      <hardwareInterface>EffortJointInterface</hardwareInterface>
      <mechanicalReduction>1</mechanicalReduction>
    </actuator>
  </transmission>
  <transmission name="robot_leg2_alpha_joint_tran">
    <type>transmission_interface/SimpleTransmission</type>
    <joint name="robot_leg2_alpha_joint">
      <hardwareInterface>EffortJointInterface</hardwareInterface>
    </joint>
    <actuator name="robot_leg2_alpha_joint_motor">
      <hardwareInterface>EffortJointInterface</hardwareInterface>
      <mechanicalReduction>1</mechanicalReduction>
    </actuator>
  </transmission>
  <transmission name="robot_leg2_beta_joint_tran">
    <type>transmission_interface/SimpleTransmission</type>
    <joint name="robot_leg2_beta_joint">
      <hardwareInterface>EffortJointInterface</hardwareInterface>
    </joint>
    <actuator name="robot_leg2_beta_joint_motor">
      <hardwareInterface>EffortJointInterface</hardwareInterface>
      <mechanicalReduction>1</mechanicalReduction>
    </actuator>
  </transmission>
  <transmission name="robot_leg2_gamma_joint_tran">
    <type>transmission_interface/SimpleTransmission</type>
    <joint name="robot_leg2_gamma_joint">
      <hardwareInterface>EffortJointInterface</hardwareInterface>
    </joint>
    <actuator name="robot_leg2_gamma_joint_motor">
      <hardwareInterface>EffortJointInterface</hardwareInterface>
      <mechanicalReduction>1</mechanicalReduction>
    </actuator>
  </transmission>
  <link name="robot_leg3_base_link"/>
  <link name="robot_leg3_body_link">
    <visual>
      <origin rpy="0 -1.5708 0" xyz="0 0 0"/>
      <geometry>
        <mesh filename="model://hbpprak_locomotion/meshes/leg/LEG_CON_low.dae"/>
      </geometry>
    </visual>
    <inertial>
      <mass value="1.0"/>
      <inertia ixx="0.01" ixy="0.0" ixz="0.0" iyy="0.01" iyz="0.0" izz="0.01"/>
    </inertial>
  </link>
  <link name="robot_leg3_delta_link">
    <visual>
      <origin xyz="0 0 0.0721"/>
      <geometry>
        <mesh filename="model://hbpprak_locomotion/meshes/leg/DELTA_low.dae"/>
      </geometry>
    </visual>
    <inertial>
      <mass value="1.0"/>
      <inertia ixx="0.01" ixy="0.0" ixz="0.0" iyy="0.01" iyz="0.0" izz="0.01"/>
    </inertial>
  </link>
  <link name="robot_leg3_alpha_link">
    <visual>
      <geometry>
        <mesh filename="model://hbpprak_locomotion/meshes/leg/ALPHA_low.dae"/>
      </geometry>
      <origin rpy="0 0 1.5708" xyz="0 0 0"/>
    </visual>
    <inertial>
      <mass value="1.0"/>
      <inertia ixx="0.01" ixy="0.0" ixz="0.0" iyy="0.01" iyz="0.0" izz="0.01"/>
    </inertial>
  </link>
  <link name="robot_leg3_beta_link">
    <visual>
      <geometry>
        <mesh filename="model://hbpprak_locomotion/meshes/leg/BETA_low.dae"/>
      </geometry>
    </visual>
    <inertial>
      <mass value="1.0"/>
      <inertia ixx="0.01" ixy="0.0" ixz="0.0" iyy="0.01" iyz="0.0" izz="0.01"/>
    </inertial>
    <collision>
      <origin rpy="0 0 0" xyz="0.085 -0.01 0"/>
      <geometry>
        <box size="0.22 0.12 0.03"/>
      </geometry>
    </collision>
  </link>
  <link name="robot_leg3_beta_fixed_link">
    <inertial>
      <mass value="0.01"/>
      <inertia ixx="0.01" ixy="0.0" ixz="0.0" iyy="0.01" iyz="0.0" izz="0.01"/>
    </inertial>
  </link>
  <link name="robot_leg3_gamma_link">
    <visual>
      <geometry>
        <mesh filename="model://hbpprak_locomotion/meshes/leg/GAMMA_low.dae"/>
      </geometry>
    </visual>
    <inertial>
      <mass value="1.0"/>
      <inertia ixx="0.01" ixy="0.0" ixz="0.0" iyy="0.01" iyz="0.0" izz="0.01"/>
    </inertial>
    <collision>
      <origin rpy="0 1.57 0" xyz="0.16 0.004 0"/>
      <geometry>
        <cylinder length="0.22" radius="0.03"/>
      </geometry>
      <contact_coefficients mu="5"/>
    </collision>
    <collision>
      <origin rpy="0 0 0" xyz="0.32 0 0"/>
      <geometry>
        <sphere radius="0.02"/>
      </geometry>
      <contact_coefficients mu="5"/>
    </collision>
  </link>
  <link name="robot_leg3_foot_link">
    <inertial>
      <mass value="0.01"/>
      <inertia ixx="0.01" ixy="0.0" ixz="0.0" iyy="0.01" iyz="0.0" izz="0.01"/>
    </inertial>
  </link>
  <joint name="robot_leg3_base_joint" type="fixed">
    <parent link="robot_base_link"/>
    <child link="robot_leg3_base_link"/>
    <origin rpy="0 0 0" xyz="-0.0673369 -0.0962107 -0.056215"/>
  </joint>
  <joint name="robot_leg3_body_joint" type="fixed">
    <parent link="robot_leg3_base_link"/>
    <child link="robot_leg3_body_link"/>
    <origin rpy="-2.35620 0 3.49066" xyz="0 0 0"/>
  </joint>
  <joint name="robot_leg3_delta_joint" type="revolute">
    <parent link="robot_leg3_body_link"/>
    <child link="robot_leg3_delta_link"/>
    <origin rpy="0 0 0" xyz="0 0 0"/>
    <axis xyz="0 0 1"/>
    <limit effort="100" lower="-1.22173" upper="1.22173" velocity="10.0"/>
  </joint>
  <joint name="robot_leg3_alpha_joint" type="revolute">
    <parent link="robot_leg3_delta_link"/>
    <child link="robot_leg3_alpha_link"/>
    <!-- old alpha part: origin xyz="0 0 0.0565" rpy="1.5708 0 0" /-->
    <origin rpy="1.5708 0 0" xyz="0 0 0.0721"/>
    <axis xyz="0 0 1"/>
    <limit effort="100" lower="-1.22173" upper="1.22173" velocity="10.0"/>
  </joint>
  <joint name="robot_leg3_beta_fixed_joint" type="fixed">
    <parent link="robot_leg3_alpha_link"/>
    <child link="robot_leg3_beta_fixed_link"/>
    <!-- old alpha part: origin xyz="0 0.089 0" rpy="1.5708 0 0" /-->
    <origin rpy="1.5708 0 0" xyz="0 0.1097 0"/>
  </joint>
  <joint name="robot_leg3_beta_joint" type="revolute">
    <parent link="robot_leg3_beta_fixed_link"/>
    <child link="robot_leg3_beta_link"/>
    <origin rpy="0 1.5708 0" xyz="0 0 0"/>
    <axis xyz="0 0 1"/>
    <limit effort="100" lower="-0.69813" upper="2.21657" velocity="10.0"/>
  </joint>
  <joint name="robot_leg3_gamma_joint" type="revolute">
    <parent link="robot_leg3_beta_link"/>
    <child link="robot_leg3_gamma_link"/>
    <!-- old beta part: origin xyz="0.2 0 0" rpy="0 0 0" /-->
    <origin rpy="0 0 0" xyz="0.195 -0.0439 0"/>
    <axis xyz="0 0 1"/>
    <limit effort="100" lower="-2.6529" upper="0.24435" velocity="10.0"/>
  </joint>
  <joint name="robot_leg3_foot_joint" type="fixed">
    <parent link="robot_leg3_gamma_link"/>
    <child link="robot_leg3_foot_link"/>
    <origin rpy="0 0 0" xyz="0.335 0 0"/>
  </joint>
  <transmission name="robot_leg3_delta_joint_tran">
    <type>transmission_interface/SimpleTransmission</type>
    <joint name="robot_leg3_delta_joint">
      <hardwareInterface>EffortJointInterface</hardwareInterface>
    </joint>
    <actuator name="robot_leg3_delta_joint_motor">
      <hardwareInterface>EffortJointInterface</hardwareInterface>
      <mechanicalReduction>1</mechanicalReduction>
    </actuator>
  </transmission>
  <transmission name="robot_leg3_alpha_joint_tran">
    <type>transmission_interface/SimpleTransmission</type>
    <joint name="robot_leg3_alpha_joint">
      <hardwareInterface>EffortJointInterface</hardwareInterface>
    </joint>
    <actuator name="robot_leg3_alpha_joint_motor">
      <hardwareInterface>EffortJointInterface</hardwareInterface>
      <mechanicalReduction>1</mechanicalReduction>
    </actuator>
  </transmission>
  <transmission name="robot_leg3_beta_joint_tran">
    <type>transmission_interface/SimpleTransmission</type>
    <joint name="robot_leg3_beta_joint">
      <hardwareInterface>EffortJointInterface</hardwareInterface>
    </joint>
    <actuator name="robot_leg3_beta_joint_motor">
      <hardwareInterface>EffortJointInterface</hardwareInterface>
      <mechanicalReduction>1</mechanicalReduction>
    </actuator>
  </transmission>
  <transmission name="robot_leg3_gamma_joint_tran">
    <type>transmission_interface/SimpleTransmission</type>
    <joint name="robot_leg3_gamma_joint">
      <hardwareInterface>EffortJointInterface</hardwareInterface>
    </joint>
    <actuator name="robot_leg3_gamma_joint_motor">
      <hardwareInterface>EffortJointInterface</hardwareInterface>
      <mechanicalReduction>1</mechanicalReduction>
    </actuator>
  </transmission>
  <link name="robot_leg4_base_link"/>
  <link name="robot_leg4_body_link">
    <visual>
      <origin rpy="0 -1.5708 0" xyz="0 0 0"/>
      <geometry>
        <mesh filename="model://hbpprak_locomotion/meshes/leg/LEG_CON_low.dae"/>
      </geometry>
    </visual>
    <inertial>
      <mass value="1.0"/>
      <inertia ixx="0.01" ixy="0.0" ixz="0.0" iyy="0.01" iyz="0.0" izz="0.01"/>
    </inertial>
  </link>
  <link name="robot_leg4_delta_link">
    <visual>
      <origin xyz="0 0 0.0721"/>
      <geometry>
        <mesh filename="model://hbpprak_locomotion/meshes/leg/DELTA_low.dae"/>
      </geometry>
    </visual>
    <inertial>
      <mass value="1.0"/>
      <inertia ixx="0.01" ixy="0.0" ixz="0.0" iyy="0.01" iyz="0.0" izz="0.01"/>
    </inertial>
  </link>
  <link name="robot_leg4_alpha_link">
    <visual>
      <geometry>
        <mesh filename="model://hbpprak_locomotion/meshes/leg/ALPHA_low.dae"/>
      </geometry>
      <origin rpy="0 0 1.5708" xyz="0 0 0"/>
    </visual>
    <inertial>
      <mass value="1.0"/>
      <inertia ixx="0.01" ixy="0.0" ixz="0.0" iyy="0.01" iyz="0.0" izz="0.01"/>
    </inertial>
  </link>
  <link name="robot_leg4_beta_link">
    <visual>
      <geometry>
        <mesh filename="model://hbpprak_locomotion/meshes/leg/BETA_low.dae"/>
      </geometry>
    </visual>
    <inertial>
      <mass value="1.0"/>
      <inertia ixx="0.01" ixy="0.0" ixz="0.0" iyy="0.01" iyz="0.0" izz="0.01"/>
    </inertial>
    <collision>
      <origin rpy="0 0 0" xyz="0.085 -0.01 0"/>
      <geometry>
        <box size="0.22 0.12 0.03"/>
      </geometry>
    </collision>
  </link>
  <link name="robot_leg4_beta_fixed_link">
    <inertial>
      <mass value="0.01"/>
      <inertia ixx="0.01" ixy="0.0" ixz="0.0" iyy="0.01" iyz="0.0" izz="0.01"/>
    </inertial>
  </link>
  <link name="robot_leg4_gamma_link">
    <visual>
      <geometry>
        <mesh filename="model://hbpprak_locomotion/meshes/leg/GAMMA_low.dae"/>
      </geometry>
    </visual>
    <inertial>
      <mass value="1.0"/>
      <inertia ixx="0.01" ixy="0.0" ixz="0.0" iyy="0.01" iyz="0.0" izz="0.01"/>
    </inertial>
    <collision>
      <origin rpy="0 1.57 0" xyz="0.16 0.004 0"/>
      <geometry>
        <cylinder length="0.22" radius="0.03"/>
      </geometry>
      <contact_coefficients mu="5"/>
    </collision>
    <collision>
      <origin rpy="0 0 0" xyz="0.32 0 0"/>
      <geometry>
        <sphere radius="0.02"/>
      </geometry>
      <contact_coefficients mu="5"/>
    </collision>
  </link>
  <link name="robot_leg4_foot_link">
    <inertial>
      <mass value="0.01"/>
      <inertia ixx="0.01" ixy="0.0" ixz="0.0" iyy="0.01" iyz="0.0" izz="0.01"/>
    </inertial>
  </link>
  <joint name="robot_leg4_base_joint" type="fixed">
    <parent link="robot_base_link"/>
    <child link="robot_leg4_base_link"/>
    <origin rpy="0 0 0" xyz="-0.20341 0.0806665 -0.056215"/>
  </joint>
  <joint name="robot_leg4_body_joint" type="fixed">
    <parent link="robot_leg4_base_link"/>
    <child link="robot_leg4_body_link"/>
    <origin rpy="-2.35620 0 0.698132" xyz="0 0 0"/>
  </joint>
  <joint name="robot_leg4_delta_joint" type="revolute">
    <parent link="robot_leg4_body_link"/>
    <child link="robot_leg4_delta_link"/>
    <origin rpy="0 0 0" xyz="0 0 0"/>
    <axis xyz="0 0 1"/>
    <limit effort="100" lower="-1.22173" upper="1.22173" velocity="10.0"/>
  </joint>
  <joint name="robot_leg4_alpha_joint" type="revolute">
    <parent link="robot_leg4_delta_link"/>
    <child link="robot_leg4_alpha_link"/>
    <!-- old alpha part: origin xyz="0 0 0.0565" rpy="1.5708 0 0" /-->
    <origin rpy="1.5708 0 0" xyz="0 0 0.0721"/>
    <axis xyz="0 0 1"/>
    <limit effort="100" lower="-1.22173" upper="1.22173" velocity="10.0"/>
  </joint>
  <joint name="robot_leg4_beta_fixed_joint" type="fixed">
    <parent link="robot_leg4_alpha_link"/>
    <child link="robot_leg4_beta_fixed_link"/>
    <!-- old alpha part: origin xyz="0 0.089 0" rpy="1.5708 0 0" /-->
    <origin rpy="1.5708 0 0" xyz="0 0.1097 0"/>
  </joint>
  <joint name="robot_leg4_beta_joint" type="revolute">
    <parent link="robot_leg4_beta_fixed_link"/>
    <child link="robot_leg4_beta_link"/>
    <origin rpy="0 1.5708 0" xyz="0 0 0"/>
    <axis xyz="0 0 1"/>
    <limit effort="100" lower="-0.69813" upper="2.21657" velocity="10.0"/>
  </joint>
  <joint name="robot_leg4_gamma_joint" type="revolute">
    <parent link="robot_leg4_beta_link"/>
    <child link="robot_leg4_gamma_link"/>
    <!-- old beta part: origin xyz="0.2 0 0" rpy="0 0 0" /-->
    <origin rpy="0 0 0" xyz="0.195 -0.0439 0"/>
    <axis xyz="0 0 1"/>
    <limit effort="100" lower="-2.6529" upper="0.24435" velocity="10.0"/>
  </joint>
  <joint name="robot_leg4_foot_joint" type="fixed">
    <parent link="robot_leg4_gamma_link"/>
    <child link="robot_leg4_foot_link"/>
    <origin rpy="0 0 0" xyz="0.335 0 0"/>
  </joint>
  <transmission name="robot_leg4_delta_joint_tran">
    <type>transmission_interface/SimpleTransmission</type>
    <joint name="robot_leg4_delta_joint">
      <hardwareInterface>EffortJointInterface</hardwareInterface>
    </joint>
    <actuator name="robot_leg4_delta_joint_motor">
      <hardwareInterface>EffortJointInterface</hardwareInterface>
      <mechanicalReduction>1</mechanicalReduction>
    </actuator>
  </transmission>
  <transmission name="robot_leg4_alpha_joint_tran">
    <type>transmission_interface/SimpleTransmission</type>
    <joint name="robot_leg4_alpha_joint">
      <hardwareInterface>EffortJointInterface</hardwareInterface>
    </joint>
    <actuator name="robot_leg4_alpha_joint_motor">
      <hardwareInterface>EffortJointInterface</hardwareInterface>
      <mechanicalReduction>1</mechanicalReduction>
    </actuator>
  </transmission>
  <transmission name="robot_leg4_beta_joint_tran">
    <type>transmission_interface/SimpleTransmission</type>
    <joint name="robot_leg4_beta_joint">
      <hardwareInterface>EffortJointInterface</hardwareInterface>
    </joint>
    <actuator name="robot_leg4_beta_joint_motor">
      <hardwareInterface>EffortJointInterface</hardwareInterface>
      <mechanicalReduction>1</mechanicalReduction>
    </actuator>
  </transmission>
  <transmission name="robot_leg4_gamma_joint_tran">
    <type>transmission_interface/SimpleTransmission</type>
    <joint name="robot_leg4_gamma_joint">
      <hardwareInterface>EffortJointInterface</hardwareInterface>
    </joint>
    <actuator name="robot_leg4_gamma_joint_motor">
      <hardwareInterface>EffortJointInterface</hardwareInterface>
      <mechanicalReduction>1</mechanicalReduction>
    </actuator>
  </transmission>
  <link name="robot_leg5_base_link"/>
  <link name="robot_leg5_body_link">
    <visual>
      <origin rpy="0 -1.5708 0" xyz="0 0 0"/>
      <geometry>
        <mesh filename="model://hbpprak_locomotion/meshes/leg/LEG_CON_low.dae"/>
      </geometry>
    </visual>
    <inertial>
      <mass value="1.0"/>
      <inertia ixx="0.01" ixy="0.0" ixz="0.0" iyy="0.01" iyz="0.0" izz="0.01"/>
    </inertial>
  </link>
  <link name="robot_leg5_delta_link">
    <visual>
      <origin xyz="0 0 0.0721"/>
      <geometry>
        <mesh filename="model://hbpprak_locomotion/meshes/leg/DELTA_low.dae"/>
      </geometry>
    </visual>
    <inertial>
      <mass value="1.0"/>
      <inertia ixx="0.01" ixy="0.0" ixz="0.0" iyy="0.01" iyz="0.0" izz="0.01"/>
    </inertial>
  </link>
  <link name="robot_leg5_alpha_link">
    <visual>
      <geometry>
        <mesh filename="model://hbpprak_locomotion/meshes/leg/ALPHA_low.dae"/>
      </geometry>
      <origin rpy="0 0 1.5708" xyz="0 0 0"/>
    </visual>
    <inertial>
      <mass value="1.0"/>
      <inertia ixx="0.01" ixy="0.0" ixz="0.0" iyy="0.01" iyz="0.0" izz="0.01"/>
    </inertial>
  </link>
  <link name="robot_leg5_beta_link">
    <visual>
      <geometry>
        <mesh filename="model://hbpprak_locomotion/meshes/leg/BETA_low.dae"/>
      </geometry>
    </visual>
    <inertial>
      <mass value="1.0"/>
      <inertia ixx="0.01" ixy="0.0" ixz="0.0" iyy="0.01" iyz="0.0" izz="0.01"/>
    </inertial>
    <collision>
      <origin rpy="0 0 0" xyz="0.085 -0.01 0"/>
      <geometry>
        <box size="0.22 0.12 0.03"/>
      </geometry>
    </collision>
  </link>
  <link name="robot_leg5_beta_fixed_link">
    <inertial>
      <mass value="0.01"/>
      <inertia ixx="0.01" ixy="0.0" ixz="0.0" iyy="0.01" iyz="0.0" izz="0.01"/>
    </inertial>
  </link>
  <link name="robot_leg5_gamma_link">
    <visual>
      <geometry>
        <mesh filename="model://hbpprak_locomotion/meshes/leg/GAMMA_low.dae"/>
      </geometry>
    </visual>
    <inertial>
      <mass value="1.0"/>
      <inertia ixx="0.01" ixy="0.0" ixz="0.0" iyy="0.01" iyz="0.0" izz="0.01"/>
    </inertial>
    <collision>
      <origin rpy="0 1.57 0" xyz="0.16 0.004 0"/>
      <geometry>
        <cylinder length="0.22" radius="0.03"/>
      </geometry>
      <contact_coefficients mu="5"/>
    </collision>
    <collision>
      <origin rpy="0 0 0" xyz="0.32 0 0"/>
      <geometry>
        <sphere radius="0.02"/>
      </geometry>
      <contact_coefficients mu="5"/>
    </collision>
  </link>
  <link name="robot_leg5_foot_link">
    <inertial>
      <mass value="0.01"/>
      <inertia ixx="0.01" ixy="0.0" ixz="0.0" iyy="0.01" iyz="0.0" izz="0.01"/>
    </inertial>
  </link>
  <joint name="robot_leg5_base_joint" type="fixed">
    <parent link="robot_base_link"/>
    <child link="robot_leg5_base_link"/>
    <origin rpy="0 0 0" xyz="-0.20341 -0.0806665 -0.056215"/>
  </joint>
  <joint name="robot_leg5_body_joint" type="fixed">
    <parent link="robot_leg5_base_link"/>
    <child link="robot_leg5_body_link"/>
    <origin rpy="-2.35620 0 2.44346" xyz="0 0 0"/>
  </joint>
  <joint name="robot_leg5_delta_joint" type="revolute">
    <parent link="robot_leg5_body_link"/>
    <child link="robot_leg5_delta_link"/>
    <origin rpy="0 0 0" xyz="0 0 0"/>
    <axis xyz="0 0 1"/>
    <limit effort="100" lower="-1.22173" upper="1.22173" velocity="10.0"/>
  </joint>
  <joint name="robot_leg5_alpha_joint" type="revolute">
    <parent link="robot_leg5_delta_link"/>
    <child link="robot_leg5_alpha_link"/>
    <!-- old alpha part: origin xyz="0 0 0.0565" rpy="1.5708 0 0" /-->
    <origin rpy="1.5708 0 0" xyz="0 0 0.0721"/>
    <axis xyz="0 0 1"/>
    <limit effort="100" lower="-1.22173" upper="1.22173" velocity="10.0"/>
  </joint>
  <joint name="robot_leg5_beta_fixed_joint" type="fixed">
    <parent link="robot_leg5_alpha_link"/>
    <child link="robot_leg5_beta_fixed_link"/>
    <!-- old alpha part: origin xyz="0 0.089 0" rpy="1.5708 0 0" /-->
    <origin rpy="1.5708 0 0" xyz="0 0.1097 0"/>
  </joint>
  <joint name="robot_leg5_beta_joint" type="revolute">
    <parent link="robot_leg5_beta_fixed_link"/>
    <child link="robot_leg5_beta_link"/>
    <origin rpy="0 1.5708 0" xyz="0 0 0"/>
    <axis xyz="0 0 1"/>
    <limit effort="100" lower="-0.69813" upper="2.21657" velocity="10.0"/>
  </joint>
  <joint name="robot_leg5_gamma_joint" type="revolute">
    <parent link="robot_leg5_beta_link"/>
    <child link="robot_leg5_gamma_link"/>
    <!-- old beta part: origin xyz="0.2 0 0" rpy="0 0 0" /-->
    <origin rpy="0 0 0" xyz="0.195 -0.0439 0"/>
    <axis xyz="0 0 1"/>
    <limit effort="100" lower="-2.6529" upper="0.24435" velocity="10.0"/>
  </joint>
  <joint name="robot_leg5_foot_joint" type="fixed">
    <parent link="robot_leg5_gamma_link"/>
    <child link="robot_leg5_foot_link"/>
    <origin rpy="0 0 0" xyz="0.335 0 0"/>
  </joint>
  <transmission name="robot_leg5_delta_joint_tran">
    <type>transmission_interface/SimpleTransmission</type>
    <joint name="robot_leg5_delta_joint">
      <hardwareInterface>EffortJointInterface</hardwareInterface>
    </joint>
    <actuator name="robot_leg5_delta_joint_motor">
      <hardwareInterface>EffortJointInterface</hardwareInterface>
      <mechanicalReduction>1</mechanicalReduction>
    </actuator>
  </transmission>
  <transmission name="robot_leg5_alpha_joint_tran">
    <type>transmission_interface/SimpleTransmission</type>
    <joint name="robot_leg5_alpha_joint">
      <hardwareInterface>EffortJointInterface</hardwareInterface>
    </joint>
    <actuator name="robot_leg5_alpha_joint_motor">
      <hardwareInterface>EffortJointInterface</hardwareInterface>
      <mechanicalReduction>1</mechanicalReduction>
    </actuator>
  </transmission>
  <transmission name="robot_leg5_beta_joint_tran">
    <type>transmission_interface/SimpleTransmission</type>
    <joint name="robot_leg5_beta_joint">
      <hardwareInterface>EffortJointInterface</hardwareInterface>
    </joint>
    <actuator name="robot_leg5_beta_joint_motor">
      <hardwareInterface>EffortJointInterface</hardwareInterface>
      <mechanicalReduction>1</mechanicalReduction>
    </actuator>
  </transmission>
  <transmission name="robot_leg5_gamma_joint_tran">
    <type>transmission_interface/SimpleTransmission</type>
    <joint name="robot_leg5_gamma_joint">
      <hardwareInterface>EffortJointInterface</hardwareInterface>
    </joint>
    <actuator name="robot_leg5_gamma_joint_motor">
      <hardwareInterface>EffortJointInterface</hardwareInterface>
      <mechanicalReduction>1</mechanicalReduction>
    </actuator>
  </transmission>
  <link name="robot_ptu_pan_link">
    <origin rpy="0 0 0" xyz="0.19 0 0"/>
    <inertial>
      <mass value="0.1"/>
      <inertia ixx="0.01" ixy="0.0" ixz="0.0" iyy="0.01" iyz="0.0" izz="0.01"/>
    </inertial>
    <collision>
      <origin rpy="0 0 0" xyz="-0.02 0 0.045"/>
      <geometry>
        <box size="0.06 0.06 0.08"/>
      </geometry>
    </collision>
    <collision>
      <origin rpy="0 0 0" xyz="-0.01 0 0.1"/>
      <geometry>
        <box size="0.05 0.25 0.04"/>
      </geometry>
    </collision>
    <visual>
      <origin rpy="0 0 0" xyz="0 0 0"/>
      <geometry>
        <mesh filename="model://hbpprak_locomotion/meshes/HEAD_low.dae"/>
      </geometry>
    </visual>
  </link>
  <link name="robot_ptu_tilt_link">
    <inertial>
      <mass value="0.1"/>
      <inertia ixx="0.01" ixy="0.0" ixz="0.0" iyy="0.01" iyz="0.0" izz="0.01"/>
    </inertial>
  </link>
  <link name="robot_/cam_xtion_link">
    <inertial>
      <mass value="0.1"/>
      <inertia ixx="0.01" ixy="0.0" ixz="0.0" iyy="0.01" iyz="0.0" izz="0.01"/>
    </inertial>
  </link>
  <link name="robot_cam_stereo_l_link">
    <inertial>
      <mass value="0.1"/>
      <inertia ixx="0.01" ixy="0.0" ixz="0.0" iyy="0.01" iyz="0.0" izz="0.01"/>
    </inertial>
  </link>
  <link name="robot_cam_stereo_r_link">
    <inertial>
      <mass value="0.1"/>
      <inertia ixx="0.01" ixy="0.0" ixz="0.0" iyy="0.01" iyz="0.0" izz="0.01"/>
    </inertial>
  </link>
  <joint name="robot_ptu_pan_joint" type="revolute">
    <parent link="robot_base_link"/>
    <child link="robot_ptu_pan_link"/>
    <origin rpy="0 0 0" xyz="0.2 0 0.15"/>
    <axis xyz="0 0 1"/>
    <limit effort="0" lower="0" upper="3.14" velocity="2.0"/>
  </joint>
  <joint name="robot_ptu_tilt_joint" type="revolute">
    <parent link="robot_ptu_pan_link"/>
    <child link="robot_ptu_tilt_link"/>
    <origin rpy="0 0 0" xyz="0 0 0.1005"/>
    <axis xyz="0 1 0"/>
    <limit effort="0" lower="0" upper="3.14" velocity="2.0"/>
  </joint>
  <joint name="robot_cam_xtion_joint" type="fixed">
    <parent link="robot_ptu_tilt_link"/>
    <child link="robot_/cam_xtion_link"/>
    <origin rpy="0 0 0" xyz="0 0 0.055"/>
  </joint>
  <joint name="robot_cam_stereo_l_joint" type="fixed">
    <parent link="robot_ptu_tilt_link"/>
    <child link="robot_cam_stereo_l_link"/>
    <origin rpy="0 0 0" xyz="0 0.0595 -0.004"/>
  </joint>
  <joint name="robot_cam_stereo_r_joint" type="fixed">
    <parent link="robot_ptu_tilt_link"/>
    <child link="robot_cam_stereo_r_link"/>
    <origin rpy="0 0 0" xyz="0 -0.0595 -0.004"/>
  </joint>
  <transmission name="robot_ptu_pan_joint_tran">
    <type>transmission_interface/SimpleTransmission</type>
    <joint name="robot_ptu_pan_joint">
      <hardwareInterface>EffortJointInterface</hardwareInterface>
    </joint>
    <actuator name="robot_ptu_pan_joint_motor">
      <hardwareInterface>EffortJointInterface</hardwareInterface>
      <mechanicalReduction>1</mechanicalReduction>
    </actuator>
  </transmission>
  <transmission name="robot_ptu_tilt_joint_tran">
    <type>transmission_interface/SimpleTransmission</type>
    <joint name="robot_ptu_tilt_joint">
      <hardwareInterface>EffortJointInterface</hardwareInterface>
    </joint>
    <actuator name="robot_ptu_tilt_joint_motor">
      <hardwareInterface>EffortJointInterface</hardwareInterface>
      <mechanicalReduction>1</mechanicalReduction>
    </actuator>
  </transmission>
  <gazebo reference="robot_cam_stereo_l_link">
    <sensor name="left_camera" type="camera">
      <pose>0 -0.05 0.18 0 -0.2 0</pose>
      <!-- estimated pose -->
      <update_rate>30.0</update_rate>
      <camera name="camera">
        <horizontal_fov>1.047</horizontal_fov>
        <image>
          <width>320</width>
          <height>240</height>
        </image>
        <clip>
          <near>0.1</near>
          <far>100</far>
        </clip>
        <noise>
          <type>gaussian</type>
          <!-- Noise is sampled independently per pixel on each frame.
                 That pixel's noise value is added to each of its color
                 channels, which at that point lie in the range [0,1]. -->
          <mean>0.0</mean>
          <stddev>0.007</stddev>
        </noise>
      </camera>
      <plugin filename="libgazebo_ros_camera.so" name="robot_left_camera">
        <alwaysOn>true</alwaysOn>
        <updateRate>0.0</updateRate>
        <cameraName>left_camera</cameraName>
        <imageTopicName>robot_left_camera</imageTopicName>
        <cameraInfoTopicName>robot_left_camera_info</cameraInfoTopicName>
        <frameName>robot_left_camera_link</frameName>
        <hackBaseline>0.07</hackBaseline>
        <distortionK1>0.0</distortionK1>
        <distortionK2>0.0</distortionK2>
        <distortionK3>0.0</distortionK3>
        <distortionT1>0.0</distortionT1>
        <distortionT2>0.0</distortionT2>
      </plugin>
    </sensor>
  </gazebo>
  <gazebo reference="robot_cam_stereo_r_link">
    <sensor name="right_camera" type="camera">
      <pose>0 0.05 0.18 0 -0.2 0</pose>
      <!-- estimated pose -->
      <update_rate>30.0</update_rate>
      <camera name="camera">
        <horizontal_fov>1.047</horizontal_fov>
        <image>
          <width>320</width>
          <height>240</height>
        </image>
        <clip>
          <near>0.1</near>
          <far>100</far>
        </clip>
        <noise>
          <type>gaussian</type>
          <!-- Noise is sampled independently per pixel on each frame.
                 That pixel's noise value is added to each of its color
                 channels, which at that point lie in the range [0,1]. -->
          <mean>0.0</mean>
          <stddev>0.007</stddev>
        </noise>
      </camera>
      <plugin filename="libgazebo_ros_camera.so" name="robot_right_camera">
        <alwaysOn>true</alwaysOn>
        <updateRate>0.0</updateRate>
        <cameraName>right_camera</cameraName>
        <imageTopicName>robot_right_camera</imageTopicName>
        <cameraInfoTopicName>robot_right_camera_info</cameraInfoTopicName>
        <frameName>robot_right_camera_link</frameName>
        <hackBaseline>0.07</hackBaseline>
        <distortionK1>0.0</distortionK1>
        <distortionK2>0.0</distortionK2>
        <distortionK3>0.0</distortionK3>
        <distortionT1>0.0</distortionT1>
        <distortionT2>0.0</distortionT2>
      </plugin>
    </sensor>
  </gazebo>
  <gazebo>
    <plugin filename="libgazebo_ros_control.so" name="gazebo_ros_control">
      <robotNamespace>/</robotNamespace>
      <robotSimType>gazebo_ros_control/DefaultRobotHWSim</robotSimType>
    </plugin>
  </gazebo>
</robot>
